Workbook

Sheet eDNA_data_ALL
A1: Date | B1: Year | C1: Reef | D1: ReefName | E1: Site_name | F1: Site_No | G1: Lat | H1: Long | I1: Voyage | J1: Project | K1: Collection organisation | L1: Collection vessel | M1: Reef_rep | N1: Site_rep | O1: PCR1_binary | P1: PCR2_binary | Q1: LOD_sample_positive | R1: PCR1_conc | S1: PCR2_conc | T1: Conc_mean
A2: 43591 | B2: 2019 | C2: Bait Reef | D2: Bait Reef (19-137) | E2: Bait1 | F2: 1 | G2: -19.794267 | H2: 149.07665 | I2: AIMSeDNA19-01 | J2: AIMS Appropriation | K2: AIMS | L2: RV Cape Ferguson | M2: 1 | N2: 1 | O2: 1 | P2: 0 | Q2: 1 | R2: 71.869911 | S2: 0 | T2: 35.934956
A3: 43591 | B3: 2019 | C3: Bait Reef | D3: Bait Reef (19-137) | E3: Bait1 | F3: 1 | G3: -19.793783 | H3: 149.07488 | I3: AIMSeDNA19-01 | J3: AIMS Appropriation | K3: AIMS | L3: RV Cape Ferguson | M3: 2 | N3: 2 | O3: 0 | P3: 1 | Q3: 1 | R3: 0 | S3: 74.693915 | T3: 37.346958
A4: 43591 | B4: 2019 | C4: Bait Reef | D4: Bait Reef (19-137) | E4: Bait1 | F4: 1 | G4: -19.79255 | H4: 149.0717 | I4: AIMSeDNA19-01 | J4: AIMS Appropriation | K4: AIMS | L4: RV Cape Ferguson | M4: 3 | N4: 3 | O4: 0 | P4: 0 | Q4: 0 | R4: 0 | S4: 0 | T4: 0
A5: 43591 | B5: 2019 | C5: Bait Reef | D5: Bait Reef (19-137) | E5: Bait1 | F5: 1 | G5: -19.793633 | H5: 149.06847 | I5: AIMSeDNA19-01 | J5: AIMS Appropriation | K5: AIMS | L5: RV Cape Ferguson | M5: 4 | N5: 4 | O5: 0 | P5: 0 | Q5: 0 | R5: 0 | S5: 0 | T5: 0
A6: 43591 | B6: 2019 | C6: Bait Reef | D6: Bait Reef (19-137) | E6: Bait1 | F6: 1 | G6: -19.797183 | H6: 149.0664 | I6: AIMSeDNA19-01 | J6: AIMS Appropriation | K6: AIMS | L6: RV Cape Ferguson | M6: 5 | N6: 5 | O6: 0 | P6: 0 | Q6: 0 | R6: 0 | S6: 0 | T6: 0
A7: 43591 | B7: 2019 | C7: Bait Reef | D7: Bait Reef (19-137) | E7: Bait1 | F7: 1 | G7: -19.800633 | H7: 149.0644 | I7: AIMSeDNA19-01 | J7: AIMS Appropriation | K7: AIMS | L7: RV Cape Ferguson | M7: 6 | N7: 6 | O7: 0 | P7: 0 | Q7: 0 | R7: 0 | S7: 0 | T7: 0
A8: 43591 | B8: 2019 | C8: Bait Reef | D8: Bait Reef (19-137) | E8: Bait1 | F8: 1 | G8: -19.803217 | H8: 149.06387 | I8: AIMSeDNA19-01 | J8: AIMS Appropriation | K8: AIMS | L8: RV Cape Ferguson | M8: 7 | N8: 7 | O8: 0 | P8: 0 | Q8: 0 | R8: 0 | S8: 0 | T8: 0
A9: 43591 | B9: 2019 | C9: Bait Reef | D9: Bait Reef (19-137) | E9: Bait1 | F9: 1 | G9: -19.806833 | H9: 149.06527 | I9: AIMSeDNA19-01 | J9: AIMS Appropriation | K9: AIMS | L9: RV Cape Ferguson | M9: 8 | N9: 8 | O9: 0 | P9: 0 | Q9: 0 | R9: 0 | S9: 0 | T9: 0
A10: 43591 | B10: 2019 | C10: Bait Reef | D10: Bait Reef (19-137) | E10: Bait1 | F10: 1 | G10: -19.806833 | H10: 149.06527 | I10: AIMSeDNA19-01 | J10: AIMS Appropriation | K10: AIMS | L10: RV Cape Ferguson | M10: 9 | N10: 9 | O10: 0 | P10: 0 | Q10: 0 | R10: 0 | S10: 0 | T10: 0
A11: 43592 | B11: 2019 | C11: Elizabeth Reef | D11: Elizabeth Reef (19-082) | E11: ER1 | F11: 1 | G11: -19.3294 | H11: 149.05355 | I11: AIMSeDNA19-01 | J11: AIMS Appropriation | K11: AIMS | L11: RV Cape Ferguson | M11: 1 | N11: 1 | O11: 0 | P11: 0 | Q11: 0 | R11: 0 | S11: 0 | T11: 0
A12: 43592 | B12: 2019 | C12: Elizabeth Reef | D12: Elizabeth Reef (19-082) | E12: ER1 | F12: 1 | G12: -19.3294 | H12: 149.05355 | I12: AIMSeDNA19-01 | J12: AIMS Appropriation | K12: AIMS | L12: RV Cape Ferguson | M12: 2 | N12: 2 | O12: 0 | P12: 0 | Q12: 0 | R12: 0 | S12: 0 | T12: 0
A13: 43592 | B13: 2019 | C13: Elizabeth Reef | D13: Elizabeth Reef (19-082) | E13: ER1 | F13: 1 | G13: -19.3294 | H13: 149.05355 | I13: AIMSeDNA19-01 | J13: AIMS Appropriation | K13: AIMS | L13: RV Cape Ferguson | M13: 3 | N13: 3 | O13: 0 | P13: 0 | Q13: 0 | R13: 0 | S13: 0 | T13: 0
... A798: 44093 | B798: 2020 | C798: Kelso Reef | D798: Kelso Reef (18-030) | E798: SW Corner | F798: 2 | G798: -18.44582 | H798: 146.99535 | I798: JCUeDNA21-01 | J798: LIRS CoTS Research Grant 2020 | K798: JCU | L798: JCU Charter | M798: 28 | N798: 13 | O798: 0 | P798: 0 | Q798: 0 | R798: 0 | S798: 0 | T798: 0
A799: 44093 | B799: 2020 | C799: Kelso Reef | D799: Kelso Reef (18-030) | E799: SW Corner | F799: 2 | G799: -18.44582 | H799: 146.99535 | I799: JCUeDNA21-01 | J799: LIRS CoTS Research Grant 2020 | K799: JCU | L799: JCU Charter | M799: 29 | N799: 14 | O799: 0 | P799: 1 | Q799: 1 | R799: ND | S799: 38.90874 | T799: 38.90874
A800: 44093 | B800: 2020 | C800: Kelso Reef | D800: Kelso Reef (18-030) | E800: SW Corner | F800: 2 | G800: -18.44582 | H800: 146.99535 | I800: JCUeDNA21-01 | J800: LIRS CoTS Research Grant 2020 | K800: JCU | L800: JCU Charter | M800: 30 | N800: 15 | O800: 1 | P800: 0 | Q800: 1 | R800: 22.65275 | S800: 0 | T800: 11.326375
A801: 44093 | B801: 2020 | C801: Rib Reef | D801: Rib Reef (18-032) | E801: North | F801: 1 | G801: -18.4755 | H801: 146.86903 | I801: JCUeDNA21-01 | J801: LIRS CoTS Research Grant 2020 | K801: JCU | L801: JCU Charter | M801: 1 | N801: 1 | O801: 0 | P801: 1 | Q801: 1 | R801: 0 | S801: 19.599677 | T801: 9.7998383
A802: 44093 | B802: 2020 | C802: Rib Reef | D802: Rib Reef (18-032) | E802: North | F802: 1 | G802: -18.4755 | H802: 146.86903 | I802: JCUeDNA21-01 | J802: LIRS CoTS Research Grant 2020 | K802: JCU | L802: JCU Charter | M802: 2 | N802: 2 | O802: 1 | P802: 0 | Q802: 1 | R802: 47.018075 | S802: 0 | T802: 23.509037
A803: 44093 | B803: 2020 | C803: Rib Reef | D803: Rib Reef (18-032) | E803: North | F803: 1 | G803: -18.4755 | H803: 146.86903 | I803: JCUeDNA21-01 | J803: LIRS CoTS Research Grant 2020 | K803: JCU | L803: JCU Charter | M803: 3 | N803: 3 | O803: 0 | P803: 1 | Q803: 1 | R803: 0 | S803: 25.201983 | T803: 12.600992
A804: 44093 | B804: 2020 | C804: Rib Reef | D804: Rib Reef (18-032) | E804: North | F804: 1 | G804: -18.4755 | H804: 146.86903 | I804: JCUeDNA21-01 | J804: LIRS CoTS Research Grant 2020 | K804: JCU | L804: JCU Charter | M804: 4 | N804: 4 | O804: 0 | P804: 1 | Q804: 1 | R804: 0 | S804: 47.901897 | T804: 23.950948
A805: 44093 | B805: 2020 | C805: Rib Reef | D805: Rib Reef (18-032) | E805: North | F805: 1 | G805: -18.4755 | H805: 146.86903 | I805: JCUeDNA21-01 | J805: LIRS CoTS Research Grant 2020 | K805: JCU | L805: JCU Charter | M805: 5 | N805: 5 | O805: 1 | P805: 1 | Q805: 1 | R805: 26.512013 | S805: 24.174881 | T805: 25.343447
A806: 44093 | B806: 2020 | C806: Rib Reef | D806: Rib Reef (18-032) | E806: North | F806: 1 | G806: -18.4755 | H806: 146.86903 | I806: JCUeDNA21-01 | J806: LIRS CoTS Research Grant 2020 | K806: JCU | L806: JCU Charter | M806: 6 | N806: 6 | O806: 1 | P806: 1 | Q806: 1 | R806: 18.284739 | S806: 72.440292 | T806: 45.362516
A807: 44093 | B807: 2020 | C807: Rib Reef | D807: Rib Reef (18-032) | E807: North | F807: 1 | G807: -18.4755 | H807: 146.86903 | I807: JCUeDNA21-01 | J807: LIRS CoTS Research Grant 2020 | K807: JCU | L807: JCU Charter | M807: 7 | N807: 7 | O807: 1 | P807: 1 | Q807: 1 | R807: 53.097815 | S807: 22.171761 | T807: 37.634788
A808: 44093 | B808: 2020 | C808: Rib Reef | D808: Rib Reef (18-032) | E808: North | F808: 1 | G808: -18.4755 | H808: 146.86903 | I808: JCUeDNA21-01 | J808: LIRS CoTS Research Grant 2020 | K808: JCU | L808: JCU Charter | M808: 8 | N808: 8 | O808: 0 | P808: 0 | Q808: 0 | R808: 0 | S808: 0 | T808: 0
A809: 44093 | B809: 2020 | C809: Rib Reef | D809: Rib Reef (18-032) | E809: North | F809: 1 | G809: -18.4755 | H809: 146.86903 | I809: JCUeDNA21-01 | J809: LIRS CoTS Research Grant 2020 | K809: JCU | L809: JCU Charter | M809: 9 | N809: 9 | O809: 1 | P809: 0 | Q809: 1 | R809: 97.770348 | S809: 0 | T809: 48.885174
A810: 44093 | B810: 2020 | C810: Rib Reef | D810: Rib Reef (18-032) | E810: North | F810: 1 | G810: -18.4755 | H810: 146.86903 | I810: JCUeDNA21-01 | J810: LIRS CoTS Research Grant 2020 | K810: JCU | L810: JCU Charter | M810: 10 | N810: 10 | O810: 1 | P810: 1 | Q810: 1 | R810: 84.744865 | S810: 21.374182 | T810: 53.059524
A811: 44093 | B811: 2020 | C811: Rib Reef | D811: Rib Reef (18-032) | E811: North | F811: 1 | G811: -18.4755 | H811: 146.86903 | I811: JCUeDNA21-01 | J811: LIRS CoTS Research Grant 2020 | K811: JCU | L811: JCU Charter | M811: 11 | N811: 11 | O811: 1 | P811: 1 | Q811: 1 | R811: 79.5226 | S811: 43.97199 | T811: 61.747295
... A2249: 44700 | B2249: 2022 | C2249: Thetford Reef | D2249: Thetford Reef (16-068) | E2249: THEDNA2 | F2249: 2 | G2249: -16.80655 | H2249: 146.188 | I2249: AIMSeDNA22-03 | J2249: CCIP-D-03 | K2249: AIMS | L2249: RV Cape Ferguson | M2249: 24 | N2249: 12 | O2249: 0 | P2249: 0 | Q2249: 0 | R2249: 0 | S2249: 0 | T2249: 0
A2250: 44700 | B2250: 2022 | C2250: Thetford Reef | D2250: Thetford Reef (16-068) | E2250: THEDNA3 | F2250: 3 | G2250: -16.79915 | H2250: 146.18912 | I2250: AIMSeDNA22-03 | J2250: CCIP-D-03 | K2250: AIMS | L2250: RV Cape Ferguson | M2250: 25 | N2250: 1 | O2250: 0 | P2250: 0 | Q2250: 0 | R2250: 0 | S2250: ND | T2250: 0
A2251: 44700 | B2251: 2022 | C2251: Thetford Reef | D2251: Thetford Reef (16-068) | E2251: THEDNA3 | F2251: 3 | G2251: -16.79915 | H2251: 146.18912 | I2251: AIMSeDNA22-03 | J2251: CCIP-D-03 | K2251: AIMS | L2251: RV Cape Ferguson | M2251: 26 | N2251: 2 | O2251: 0 | P2251: 0 | Q2251: 0 | R2251: 0 | S2251: 0 | T2251: 0
A2252: 44700 | B2252: 2022 | C2252: Thetford Reef | D2252: Thetford Reef (16-068) | E2252: THEDNA3 | F2252: 3 | G2252: -16.79915 | H2252: 146.18912 | I2252: AIMSeDNA22-03 | J2252: CCIP-D-03 | K2252: AIMS | L2252: RV Cape Ferguson | M2252: 27 | N2252: 3 | O2252: 0 | P2252: 0 | Q2252: 0 | R2252: 0 | S2252: 0 | T2252: 0
A2253: 44700 | B2253: 2022 | C2253: Thetford Reef | D2253: Thetford Reef (16-068) | E2253: THEDNA3 | F2253: 3 | G2253: -16.79915 | H2253: 146.18912 | I2253: AIMSeDNA22-03 | J2253: CCIP-D-03 | K2253: AIMS | L2253: RV Cape Ferguson | M2253: 28 | N2253: 4 | O2253: 0 | P2253: 0 | Q2253: 0 | R2253: 0 | S2253: 0 | T2253: 0
A2254: 44700 | B2254: 2022 | C2254: Thetford Reef | D2254: Thetford Reef (16-068) | E2254: THEDNA3 | F2254: 3 | G2254: -16.79915 | H2254: 146.18912 | I2254: AIMSeDNA22-03 | J2254: CCIP-D-03 | K2254: AIMS | L2254: RV Cape Ferguson | M2254: 29 | N2254: 5 | O2254: 0 | P2254: 0 | Q2254: 0 | R2254: 0 | S2254: 0 | T2254: 0
A2255: 44700 | B2255: 2022 | C2255: Thetford Reef | D2255: Thetford Reef (16-068) | E2255: THEDNA3 | F2255: 3 | G2255: -16.79915 | H2255: 146.18912 | I2255: AIMSeDNA22-03 | J2255: CCIP-D-03 | K2255: AIMS | L2255: RV Cape Ferguson | M2255: 30 | N2255: 6 | O2255: 0 | P2255: 0 | Q2255: 0 | R2255: 0 | S2255: 0 | T2255: 0
A2256: 44700 | B2256: 2022 | C2256: Thetford Reef | D2256: Thetford Reef (16-068) | E2256: THEDNA3 | F2256: 3 | G2256: -16.79915 | H2256: 146.18912 | I2256: AIMSeDNA22-03 | J2256: CCIP-D-03 | K2256: AIMS | L2256: RV Cape Ferguson | M2256: 31 | N2256: 7 | O2256: 0 | P2256: 0 | Q2256: 0 | R2256: 0 | S2256: 0 | T2256: 0
A2257: 44700 | B2257: 2022 | C2257: Thetford Reef | D2257: Thetford Reef (16-068) | E2257: THEDNA3 | F2257: 3 | G2257: -16.79915 | H2257: 146.18912 | I2257: AIMSeDNA22-03 | J2257: CCIP-D-03 | K2257: AIMS | L2257: RV Cape Ferguson | M2257: 32 | N2257: 8 | O2257: 0 | P2257: 0 | Q2257: 0 | R2257: 0 | S2257: 0 | T2257: 0
A2258: 44700 | B2258: 2022 | C2258: Thetford Reef | D2258: Thetford Reef (16-068) | E2258: THEDNA3 | F2258: 3 | G2258: -16.79915 | H2258: 146.18912 | I2258: AIMSeDNA22-03 | J2258: CCIP-D-03 | K2258: AIMS | L2258: RV Cape Ferguson | M2258: 33 | N2258: 9 | O2258: 0 | P2258: 0 | Q2258: 0 | R2258: 0 | S2258: 0 | T2258: 0
A2259: 44700 | B2259: 2022 | C2259: Thetford Reef | D2259: Thetford Reef (16-068) | E2259: THEDNA3 | F2259: 3 | G2259: -16.79915 | H2259: 146.18912 | I2259: AIMSeDNA22-03 | J2259: CCIP-D-03 | K2259: AIMS | L2259: RV Cape Ferguson | M2259: 34 | N2259: 10 | O2259: 0 | P2259: 0 | Q2259: 0 | R2259: 0 | S2259: 0 | T2259: 0
A2260: 44700 | B2260: 2022 | C2260: Thetford Reef | D2260: Thetford Reef (16-068) | E2260: THEDNA3 | F2260: 3 | G2260: -16.79915 | H2260: 146.18912 | I2260: AIMSeDNA22-03 | J2260: CCIP-D-03 | K2260: AIMS | L2260: RV Cape Ferguson | M2260: 35 | N2260: 11 | O2260: 0 | P2260: 0 | Q2260: 0 | R2260: 0 | S2260: 0 | T2260: 0
A2261: 44700 | B2261: 2022 | C2261: Thetford Reef | D2261: Thetford Reef (16-068) | E2261: THEDNA3 | F2261: 3 | G2261: -16.79915 | H2261: 146.18912 | I2261: AIMSeDNA22-03 | J2261: CCIP-D-03 | K2261: AIMS | L2261: RV Cape Ferguson | M2261: 36 | N2261: 12 | O2261: 0 | P2261: 0 | Q2261: 0 | R2261: 0 | S2261: 0 | T2261: 0
...

Sheet Spatial data for repository
A1: name | B1: longitude | C1: latitude
A2: =_xlfn.CONCAT(eDNA_data_ALL!D2,"_site",eDNA_data_ALL!F2) -> Bait Reef (19-137)_site1 | B2: =eDNA_data_ALL!H2 -> 149.07665 | C2: =eDNA_data_ALL!G2 -> -19.794267
A3: =_xlfn.CONCAT(eDNA_data_ALL!D3,"_site",eDNA_data_ALL!F3) -> Bait Reef (19-137)_site1 | B3: =eDNA_data_ALL!H3 -> 149.07488 | C3: =eDNA_data_ALL!G3 -> -19.793783
A4: =_xlfn.CONCAT(eDNA_data_ALL!D4,"_site",eDNA_data_ALL!F4) -> Bait Reef (19-137)_site1 | B4: =eDNA_data_ALL!H4 -> 149.0717 | C4: =eDNA_data_ALL!G4 -> -19.79255
A5: =_xlfn.CONCAT(eDNA_data_ALL!D5,"_site",eDNA_data_ALL!F5) -> Bait Reef (19-137)_site1 | B5: =eDNA_data_ALL!H5 -> 149.06847 | C5: =eDNA_data_ALL!G5 -> -19.793633
A6: =_xlfn.CONCAT(eDNA_data_ALL!D6,"_site",eDNA_data_ALL!F6) -> Bait Reef (19-137)_site1 | B6: =eDNA_data_ALL!H6 -> 149.0664 | C6: =eDNA_data_ALL!G6 -> -19.797183
A7: =_xlfn.CONCAT(eDNA_data_ALL!D7,"_site",eDNA_data_ALL!F7) -> Bait Reef (19-137)_site1 | B7: =eDNA_data_ALL!H7 -> 149.0644 | C7: =eDNA_data_ALL!G7 -> -19.800633
A8: =_xlfn.CONCAT(eDNA_data_ALL!D8,"_site",eDNA_data_ALL!F8) -> Bait Reef (19-137)_site1 | B8: =eDNA_data_ALL!H8 -> 149.06387 | C8: =eDNA_data_ALL!G8 -> -19.803217
A9: =_xlfn.CONCAT(eDNA_data_ALL!D9,"_site",eDNA_data_ALL!F9) -> Bait Reef (19-137)_site1 | B9: =eDNA_data_ALL!H9 -> 149.06527 | C9: =eDNA_data_ALL!G9 -> -19.806833
A10: =_xlfn.CONCAT(eDNA_data_ALL!D11,"_site",eDNA_data_ALL!F11) -> Elizabeth Reef (19-082)_site1 | B10: =eDNA_data_ALL!H11 -> 149.05355 | C10: =eDNA_data_ALL!G11 -> -19.3294
A11: =_xlfn.CONCAT(eDNA_data_ALL!D21,"_site",eDNA_data_ALL!F21) -> Elizabeth Reef (19-082)_site2 | B11: =eDNA_data_ALL!H21 -> 149.05045 | C11: =eDNA_data_ALL!G21 -> -19.334333
A12: =_xlfn.CONCAT(eDNA_data_ALL!D29,"_site",eDNA_data_ALL!F29) -> Bowden Reef (19-019)_site1 | B12: =eDNA_data_ALL!H29 -> 147.92628 | C12: =eDNA_data_ALL!G29 -> -19.0381
A13: =_xlfn.CONCAT(eDNA_data_ALL!D39,"_site",eDNA_data_ALL!F39) -> Bowden Reef (19-019)_site2 | B13: =eDNA_data_ALL!H39 -> 147.93625 | C13: =eDNA_data_ALL!G39 -> -19.0308
A14: =_xlfn.CONCAT(eDNA_data_ALL!D89,"_site",eDNA_data_ALL!F89) -> Davies Reef (18-096)_site1 | B14: =eDNA_data_ALL!H89 -> 147.6294 | C14: =eDNA_data_ALL!G89 -> -18.826283
A15: =_xlfn.CONCAT(eDNA_data_ALL!D99,"_site",eDNA_data_ALL!F99) -> Davies Reef (18-096)_site2 | B15: =eDNA_data_ALL!H99 -> 147.63548 | C15: =eDNA_data_ALL!G99 -> -18.830867
A16: =_xlfn.CONCAT(eDNA_data_ALL!D168,"_site",eDNA_data_ALL!F168) -> Lizard Island Reef (Lagoon) (14-116d)_site4 | B16: =eDNA_data_ALL!H168 -> 145.45497 | C16: =eDNA_data_ALL!G168 -> -14.68748
A17: =_xlfn.CONCAT(eDNA_data_ALL!D178,"_site",eDNA_data_ALL!F178) -> Lizard Island Reef (Lagoon) (14-116d)_site1 | B17: =eDNA_data_ALL!H178 -> 145.43935 | C17: =eDNA_data_ALL!G178 -> -14.68384
A18: =_xlfn.CONCAT(eDNA_data_ALL!D228,"_site",eDNA_data_ALL!F228) -> Lizard Island Reef (North East) (14-116b)_site5 | B18: =eDNA_data_ALL!H228 -> 145.4536 | C18: =eDNA_data_ALL!G228 -> -14.64599
A19: =_xlfn.CONCAT(eDNA_data_ALL!D246,"_site",eDNA_data_ALL!F246) -> Lizard Island Reef (North West) (14-116a)_site3 | B19: =eDNA_data_ALL!H246 -> 145.44887 | C19: =eDNA_data_ALL!G246 -> -14.66158
A20: =_xlfn.CONCAT(eDNA_data_ALL!D288,"_site",eDNA_data_ALL!F288) -> Lizard Island Reef (Lagoon) (14-116d)_site2 | B20: =eDNA_data_ALL!H288 -> 145.44092 | C20: =eDNA_data_ALL!G288 -> -14.67435
A21: =_xlfn.CONCAT(eDNA_data_ALL!D333,"_site",eDNA_data_ALL!F333) -> Elizabeth Reef (19-082)_site2 | B21: =eDNA_data_ALL!H333 -> 149.05045 | C21: =eDNA_data_ALL!G333 -> -19.334333
A22: =_xlfn.CONCAT(eDNA_data_ALL!D394,"_site",eDNA_data_ALL!F394) -> Bowden Reef (19-019)_site1 | B22: =eDNA_data_ALL!H394 -> 147.92628 | C22: =eDNA_data_ALL!G394 -> -19.0381
A23: =_xlfn.CONCAT(eDNA_data_ALL!D499,"_site",eDNA_data_ALL!F499) -> Keeper Reef (18-079)_site1 | B23: =eDNA_data_ALL!H499 -> 147.26901 | C23: =eDNA_data_ALL!G499 -> -18.74352
A24: =_xlfn.CONCAT(eDNA_data_ALL!D514,"_site",eDNA_data_ALL!F514) -> Keeper Reef (18-079)_site2 | B24: =eDNA_data_ALL!H514 -> 147.26491 | C24: =eDNA_data_ALL!G514 -> -18.74244
A25: =_xlfn.CONCAT(eDNA_data_ALL!D679,"_site",eDNA_data_ALL!F679) -> Moore Reef (16-071)_site4 | B25: =eDNA_data_ALL!H679 -> 146.19533 | C25: =eDNA_data_ALL!G679 -> -16.88465
A26: =_xlfn.CONCAT(eDNA_data_ALL!D694,"_site",eDNA_data_ALL!F694) -> Moore Reef (16-071)_site5 | B26: =eDNA_data_ALL!H694 -> 146.21861 | C26: =eDNA_data_ALL!G694 -> -16.84737
A27: =_xlfn.CONCAT(eDNA_data_ALL!D711,"_site",eDNA_data_ALL!F711) -> Thetford Reef (16-068)_site4 | B27: =eDNA_data_ALL!H711 -> 146.18799 | C27: =eDNA_data_ALL!G711 -> -16.79705
A28: =_xlfn.CONCAT(eDNA_data_ALL!D726,"_site",eDNA_data_ALL!F726) -> Thetford Reef (16-068)_site5 | B28: =eDNA_data_ALL!H726 -> 146.17595 | C28: =eDNA_data_ALL!G726 -> -16.81035
A29: =_xlfn.CONCAT(eDNA_data_ALL!D741,"_site",eDNA_data_ALL!F741) -> Elford Reef (16-073)_site3 | B29: =eDNA_data_ALL!H741 -> 146.21922 | C29: =eDNA_data_ALL!G741 -> -16.90731
A30: =_xlfn.CONCAT(eDNA_data_ALL!D756,"_site",eDNA_data_ALL!F756) -> Elford Reef (16-073)_site2 | B30: =eDNA_data_ALL!H756 -> 146.25456 | C30: =eDNA_data_ALL!G756 -> -16.91548
A31: =_xlfn.CONCAT(eDNA_data_ALL!D771,"_site",eDNA_data_ALL!F771) -> Kelso Reef (18-030)_site1 | B31: =eDNA_data_ALL!H771 -> 146.98662 | C31: =eDNA_data_ALL!G771 -> -18.43156
A32: =_xlfn.CONCAT(eDNA_data_ALL!D786,"_site",eDNA_data_ALL!F786) -> Kelso Reef (18-030)_site2 | B32: =eDNA_data_ALL!H786 -> 146.99535 | C32: =eDNA_data_ALL!G786 -> -18.44582
A33: =_xlfn.CONCAT(eDNA_data_ALL!D801,"_site",eDNA_data_ALL!F801) -> Rib Reef (18-032)_site1 | B33: =eDNA_data_ALL!H801 -> 146.86903 | C33: =eDNA_data_ALL!G801 -> -18.4755
A34: =_xlfn.CONCAT(eDNA_data_ALL!D816,"_site",eDNA_data_ALL!F816) -> Rib Reef (18-032)_site2 | B34: =eDNA_data_ALL!H816 -> 146.86782 | C34: =eDNA_data_ALL!G816 -> -18.47943
A35: =_xlfn.CONCAT(eDNA_data_ALL!D831,"_site",eDNA_data_ALL!F831) -> Moore Reef (16-071)_site1 | B35: =eDNA_data_ALL!H831 -> 146.23963 | C35: =eDNA_data_ALL!G831 -> -16.864083
A36: =_xlfn.CONCAT(eDNA_data_ALL!D843,"_site",eDNA_data_ALL!F843) -> Moore Reef (16-071)_site2 | B36: =eDNA_data_ALL!H843 -> 146.23637 | C36: =eDNA_data_ALL!G843 -> -16.855183
A37: =_xlfn.CONCAT(eDNA_data_ALL!D855,"_site",eDNA_data_ALL!F855) -> Moore Reef (16-071)_site3 | B37: =eDNA_data_ALL!H855 -> 146.22685 | C37: =eDNA_data_ALL!G855 -> -16.847367
A38: =_xlfn.CONCAT(eDNA_data_ALL!D867,"_site",eDNA_data_ALL!F867) -> Thetford Reef (16-068)_site1 | B38: =eDNA_data_ALL!H867 -> 146.17928 | C38: =eDNA_data_ALL!G867 -> -16.81195
A39: =_xlfn.CONCAT(eDNA_data_ALL!D879,"_site",eDNA_data_ALL!F879) -> Thetford Reef (16-068)_site2 | B39: =eDNA_data_ALL!H879 -> 146.188 | C39: =eDNA_data_ALL!G879 -> -16.80655
A40: =_xlfn.CONCAT(eDNA_data_ALL!D891,"_site",eDNA_data_ALL!F891) -> Thetford Reef (16-068)_site3 | B40: =eDNA_data_ALL!H891 -> 146.18912 | C40: =eDNA_data_ALL!G891 -> -16.79915
...

Sheet eDNAVoyages
A1: Vessel | B1: Voyage | C1: Departure Date | D1: Return Date
A2: RV Cape Ferguson | B2: AIMSeDNA19-01 | C2: 43591 | D2: 43600
A3: LIRS dinghy | B3: AIMSeDNA20-01 | C3: 43701 | D3: 43709
A4: RV Cape Ferguson | B4: AIMSeDNA20-02 | C4: 43963 | D4: 43970
A5: Kirsty K | B5: AIMSeDNA21-01 | C5: 44068 | D5: 44075
A6: JCU Charter | B6: JCUeDNA21-01 | C6: 44088 | D6: 44093
A7: RV Cape Ferguson | B7: AIMSeDNA21-02 | C7: 44329 | D7: 44341
A8: Kirsty K | B8: AIMSeDNA22-01 | C8: 44427 | D8: 44435
A9: JCU Charter | B9: JCUeDNA22-01 | C9: 44527 | D9: 44529
A10: RV Solander | B10: AIMSeDNA22-02 | C10: 44648 | D10: 44654
A11: RV Cape Ferguson | B11: AIMSeDNA22-03 | C11: 44694 | D11: 44705
A12: Kirsty K | B12: AIMSeDNA23-01 | C12: 44793 | D12: 44799
A13: JCU Charter | B13: JCUeDNA23-01 | C13: 44860 | D13: 44866
... A24: Reef Resilience | B24: FMPCRS 2025-02 | C24: 45693 | D24: 45702
A25: Odyssey | B25: 136 | C25: 45747 | D25: 45760
A26: Infamis | B26: 41 | C26: 45751 | D26: 45763
A27: RV Solander | B27: AIMSeDNA25-04 | C27: 45804 | D27: 45817
A28: Odyssey | B28: 142 | C28: 45869 | D28: 45880
A29: RV Cape Ferguson | B29: AIMSeDNA26-01 | C29: 45870 | D29: 45872
A30: Infamis | B30: 45 | C30: 45882 | D30: 45894
A31: Kirsty K | B31: AIMSeDNA26-02 | C31: 45922 | D31: 45928
